<?xml version="1.0"?>
<robot xmlns:xacro="http://www.ros.org/wiki/xacro" name="joint_model_macro">

  <xacro:macro name="joint_model" params="prefix">
        Svart kube fra origo, med ein raud disk på toppen, som har ein kvit viser langs radiusen på overflata.
    <!-- Stator link: svart boks -->
    <link name="${prefix}stator_link">
      <visual>
        <geometry>
          <box size="0.102 0.102 0.102"/>
        </geometry>
        <material name="black">
          <color rgba="0 0 0 1"/>
        </material>
      </visual>
    </link>

    <!-- Rotor link: rød sylinder -->
    <link name="${prefix}rotor_link">
      <visual>
        <geometry>
          <cylinder radius="0.025" length="0.01"/>
        </geometry>
        <material name="red">
          <color rgba="1 0 0 1"/>
        </material>
      </visual>
    </link>

    <!-- Angle link: hvit boks -->
    <link name="${prefix}angle_link">
      <visual>
        <geometry>
          <box size="0.025 0.002 0.002"/>
        </geometry>
        <material name="white">
          <color rgba="1 1 1 1"/>
        </material>
      </visual>
    </link>

    <!-- stator_joint: Fixed joint mellom base_link (definert i hovedfilen) og stator_link -->
    <joint name="${prefix}stator_joint" type="fixed">
      <parent link="${prefix}base_link"/>
      <child link="${prefix}stator_link"/>
      <!-- Plasserer stator_link slik at midten (0.102/2 = 0.051 m) ligger over base_link -->
      <origin xyz="0 0 0.051" rpy="0 0 0"/>
    </joint>

    <!-- angle: Revolute joint mellom stator_link og rotor_link -->
    <joint name="${prefix}angle" type="revolute">
      <parent link="${prefix}stator_link"/>
      <child link="${prefix}rotor_link"/>
      <!-- Plasserer rotor_link slik at dens bunn møter toppen av stator_link (0.102 m) -->
      <origin xyz="0 0 0.053" rpy="0 0 0"/>
      <axis xyz="0 0 1"/>
      <limit effort="1.0" velocity="1.0" lower="-3.14" upper="3.14"/>
    </joint>

    <!-- indicator: Fixed joint mellom rotor_link og angle_link -->
    <joint name="${prefix}indicator" type="fixed">
      <parent link="${prefix}rotor_link"/>
      <child link="${prefix}angle_link"/>
      <!-- Plasserer angle_link slik at den stikker ut fra rotoren:
           Eksempelvis 0.0125 m i x og 0.005 m i z -->
      <origin xyz="0.0125 0 0.005" rpy="0 0 0"/>
    </joint>

  </xacro:macro>
</robot>

