<?xml version="1.0"?>
<robot xmlns:xacro="http://www.ros.org/wiki/xacro" name="qube_macro">
  <!-- Parametere -->
  <xacro:property name="box_size" value="0.102"/>          <!-- Størrelse på den svarte boksen -->
  <xacro:property name="disk_radius" value="0.025"/>       <!-- Radius for den røde disken -->
  <xacro:property name="disk_thickness" value="0.01"/>      <!-- Tykkelse på den røde disken -->
  <xacro:property name="indicator_length" value="0.025"/>   <!-- Lengde på den hvite indikatoren -->
  <xacro:property name="indicator_width" value="0.002"/>
  <xacro:property name="indicator_height" value="0.002"/>
  
  <!-- Kalkulerte størrelser -->
  <xacro:property name="half_box_size" value="$(expr ${box_size} / 2)"/>
  <xacro:property name="disk_z" value="$(expr ${box_size} + ${disk_thickness} / 2)"/>

  <!-- Makro: 'qube' med valgfritt prefix for gjenbrukbarhet -->
  <xacro:macro name="qube" params="prefix">
    <!-- Svarte boksen (stator) -->
    <link name="${prefix}stator_link">
      <visual>
        <geometry>
          <box size="${box_size} ${box_size} ${box_size}"/>
        </geometry>
        <material name="black">
          <color rgba="0 0 0 1"/>
        </material>
      </visual>
    </link>

    <!-- Røde disken (rotor) -->
    <link name="${prefix}rotor_link">
      <visual>
        <geometry>
          <cylinder radius="${disk_radius}" length="${disk_thickness}"/>
        </geometry>
        <material name="red">
          <color rgba="1 0 0 1"/>
        </material>
      </visual>
    </link>

    <!-- Hvite indikatoren -->
    <link name="${prefix}indicator_link">
      <visual>
        <geometry>
          <box size="${indicator_length} ${indicator_width} ${indicator_height}"/>
        </geometry>
        <material name="white">
          <color rgba="1 1 1 1"/>
        </material>
      </visual>
    </link>

    <!-- Fiksert joint: kobler base_link til den svarte boksen -->
    <joint name="${prefix}stator_joint" type="fixed">
      <parent link="${prefix}base_link"/>
      <child link="${prefix}stator_link"/>
      <origin xyz="0 0 ${half_box_size}" rpy="0 0 0"/>
    </joint>

    <!-- Revolute joint: disken spinner i forhold til boksen -->
    <joint name="${prefix}disk_joint" type="revolute">
      <parent link="${prefix}stator_link"/>
      <child link="${prefix}rotor_link"/>
      <origin xyz="0 0 ${disk_z}" rpy="0 0 0"/>
      <axis xyz="0 0 1"/>
      <limit lower="-3.14" upper="3.14" effort="1.0" velocity="1.0"/>
    </joint>

    <!-- Fiksert joint: fester den hvite indikatoren til disken -->
    <joint name="${prefix}indicator_joint" type="fixed">
      <parent link="${prefix}rotor_link"/>
      <child link="${prefix}indicator_link"/>
      <!-- Plasserer indikatoren til å stikke ut fra disken (langs x-aksen) -->
      <origin xyz="${disk_radius} 0 0" rpy="0 0 0"/>
    </joint>
  </xacro:macro>
</robot>
